<?xml version='1.0'?>
<sdf version='1.6'>
  <model name='KTbot_V8'>
    <link name='base'>
      <pose frame=''>0.000537 0.007761 0.214993 0 -0 0</pose>
      <inertial>
        <mass>0.41</mass>
        <inertia>
          <ixx>0.00062306</ixx>
          <ixy>0</ixy>
          <ixz>0</ixz>
          <iyy>0.00076912</iyy>
          <iyz>0</iyz>
          <izz>0.00139144</izz>
        </inertia>
        <pose frame=''>0 0 0 0 -0 0</pose>
      </inertial>
      <visual name='visual'>
        <pose frame=''>0 0 0 0 -0 0</pose>
        <geometry>
          <box>
            <size>0.15 0.135 0.0033</size>
          </box>
        </geometry>
        <material>
          <lighting>1</lighting>
          <script>
            <uri>file://media/materials/scripts/gazebo.material</uri>
            <name>Gazebo/White</name>
          </script>
          <ambient>1 1 1 1</ambient>
          <diffuse>0.2 0.2 0.2 1</diffuse>
          <specular>0.1 0.1 0.1 1</specular>
          <emissive>0 0 0 1</emissive>
        </material>
        <transparency>0.5</transparency>
      </visual>
      <collision name='collision'>
        <pose frame=''>0 0 0 0 -0 0</pose>
        <geometry>
          <box>
            <size>0.15 0.135 0.0033</size>
          </box>
        </geometry>
      </collision>

      <visual name='caster_visual'>
        <pose frame=''>0.0 -0.05 -0.038 0 -0 0</pose>
        <geometry>
          <sphere>
            <radius>0.01</radius>
          </sphere>
        </geometry>
        <material>
          <script>
            <uri>file://media/materials/scripts/gazebo.material</uri>
            <name>Gazebo/Grey</name>
          </script>
          <ambient>1 1 1 1</ambient>
          <diffuse>0.2 0.2 0.2 1</diffuse>
          <specular>0.8 0.8 0.8 1</specular>
          <emissive>0 0 0 1</emissive>
        </material>
      </visual>

      <collision name='caster_collision'>
        <pose frame=''>0.0 -0.05 -0.038 0 -0 0</pose>
        <geometry>
          <sphere>
            <radius>0.01</radius>
          </sphere>
        </geometry>
        <surface>
          <friction>
            <ode>
              <mu>0.0</mu>
              <mu2>0.0</mu2>
              <slip1>1.0</slip1>
              <slip2>1.0</slip2>
            </ode>
          </friction>
        </surface>
      </collision>
    </link>
    <link name='left_servo'>
      <pose frame=''>-0.056463 0.041761 0.20111 0 0 -3.14159</pose>
      <inertial>
        <mass>0.052</mass>
        <inertia>
          <ixx>1.188e-05</ixx>
          <ixy>0</ixy>
          <ixz>0</ixz>
          <iyy>8.02e-06</iyy>
          <iyz>0</iyz>
          <izz>1.448e-05</izz>
        </inertia>
        <pose frame=''>0 0 0 0 -0 0</pose>
      </inertial>
      <visual name='visual'>
        <pose frame=''>0 0 0 0 -0 0</pose>
        <geometry>
          <box>
            <size>0.035 0.046 0.025</size>
          </box>
        </geometry>
        <material>
          <lighting>1</lighting>
          <script>
            <uri>file://media/materials/scripts/gazebo.material</uri>
            <name>Gazebo/Black</name>
          </script>
          <ambient>0 0 0 1</ambient>
          <diffuse>0.1 0.1 0.1 1</diffuse>
          <specular>0.01 0.01 0.01 1</specular>
          <emissive>0 0 0 1</emissive>
        </material>
      </visual>
      <collision name='collision'>
        <pose frame=''>0 0 0 0 -0 0</pose>
        <geometry>
          <box>
            <size>0.035 0.046 0.025</size>
          </box>
        </geometry>
      </collision>
    </link>
    <link name='right_servo'>
      <pose frame=''>0.057537 0.041761 0.20111 0 -0 0</pose>
      <inertial>
        <mass>0.052</mass>
        <inertia>
          <ixx>1.188e-05</ixx>
          <ixy>0</ixy>
          <ixz>0</ixz>
          <iyy>8.02e-06</iyy>
          <iyz>0</iyz>
          <izz>1.448e-05</izz>
        </inertia>
        <pose frame=''>0 0 0 0 -0 0</pose>
      </inertial>
      <visual name='visual'>
        <pose frame=''>0 0 0 0 -0 0</pose>
        <geometry>
          <box>
            <size>0.035 0.046 0.025</size>
          </box>
        </geometry>
        <material>
          <script>
            <uri>file://media/materials/scripts/gazebo.material</uri>
            <name>Gazebo/Black</name>
          </script>
          <ambient>0 0 0 1</ambient>
          <diffuse>0.1 0.1 0.1 1</diffuse>
          <specular>0.01 0.01 0.01 1</specular>
          <emissive>0 0 0 1</emissive>
        </material>
      </visual>
      <collision name='collision'>
        <pose frame=''>0 0 0 0 -0 0</pose>
        <geometry>
          <box>
            <size>0.035 0.046 0.025</size>
          </box>
        </geometry>
      </collision>
    </link>
    <link name='left_wheel'>
      <pose frame=''>-0.086463 0.051761 0.20111 0 1.57079 0</pose>
      <inertial>
        <mass>0.03</mass>
        <inertia>
          <ixx>8.48e-06</ixx>
          <ixy>0</ixy>
          <ixz>0</ixz>
          <iyy>8.48e-06</iyy>
          <iyz>0</iyz>
          <izz>1.584e-05</izz>
        </inertia>
        <pose frame=''>0 0 0 0 -0 0</pose>
      </inertial>
      <visual name='visual'>
        <pose frame=''>0 0 0 0 -0 0</pose>
        <geometry>
          <cylinder>
            <radius>0.0325</radius>
            <length>0.015</length>
          </cylinder>
        </geometry>
        <material>
          <script>
            <uri>file://media/materials/scripts/gazebo.material</uri>
            <name>Gazebo/Black</name>
          </script>
          <ambient>0 0 0 1</ambient>
          <diffuse>0.1 0.1 0.1 1</diffuse>
          <specular>0 0 0 1</specular>
          <emissive>0 0 0 1</emissive>
        </material>
      </visual>
      <collision name='collision'>
        <pose frame=''>0 0 0 0 -0 0</pose>
        <geometry>
          <cylinder>
            <radius>0.0325</radius>
            <length>0.015</length>
          </cylinder>
        </geometry>
        <surface>
          <friction>
            <ode>
              <mu>100</mu>
              <mu2>50</mu2>
              <slip1>0.0</slip1>
              <slip2>0.0</slip2>
            </ode>
          </friction>
        </surface>
      </collision>
    </link>
    <link name='right_wheel'>
      <pose frame=''>0.087537 0.051761 0.20111 0 1.57079 0</pose>
      <inertial>
        <mass>0.03</mass>
        <inertia>
          <ixx>8.48e-06</ixx>
          <ixy>0</ixy>
          <ixz>0</ixz>
          <iyy>8.48e-06</iyy>
          <iyz>0</iyz>
          <izz>1.584e-05</izz>
        </inertia>
        <pose frame=''>0 0 0 0 -0 0</pose>
      </inertial>
      <visual name='visual'>
        <pose frame=''>0 0 0 0 -0 0</pose>
        <geometry>
          <cylinder>
            <radius>0.0325</radius>
            <length>0.015</length>
          </cylinder>
        </geometry>
        <material>
          <script>
            <uri>file://media/materials/scripts/gazebo.material</uri>
            <name>Gazebo/Black</name>
          </script>
          <ambient>0 0 0 1</ambient>
          <diffuse>0.1 0.1 0.1 1</diffuse>
          <specular>0 0 0 1</specular>
          <emissive>0 0 0 1</emissive>
        </material>
      </visual>
      <collision name='collision'>
        <pose frame=''>0 0 0 0 -0 0</pose>
        <geometry>
          <cylinder>
            <radius>0.0325</radius>
            <length>0.015</length>
          </cylinder>
        </geometry>
        <surface>
          <friction>
            <ode>
              <mu>100</mu>
              <mu2>50</mu2>
              <slip1>0.0</slip1>
              <slip2>0.0</slip2>
            </ode>
          </friction>
        </surface>
      </collision>
    </link>
    <link name='back_stack'>
      <pose frame=''>0.000271 -0.039485 0.195938 0 -0 0</pose>
      <inertial>
        <mass>0.01</mass>
        <inertia>
          <ixx>1.98e-06</ixx>
          <ixy>0</ixy>
          <ixz>0</ixz>
          <iyy>2.3e-06</iyy>
          <iyz>0</iyz>
          <izz>2.35e-06</izz>
        </inertia>
        <pose frame=''>0 0 0 0 -0 0</pose>
      </inertial>
      <visual name='visual'>
        <pose frame=''>0 0 0 0 -0 0</pose>
        <geometry>
          <box>
            <size>0.04 0.035 0.034</size>
          </box>
        </geometry>
        <material>
          <script>
            <uri>file://media/materials/scripts/gazebo.material</uri>
            <name>Gazebo/White</name>
          </script>
          <ambient>1 1 1 1</ambient>
          <diffuse>0.1 0.1 0.1 1</diffuse>
          <specular>0.1 0.1 0.1 1</specular>
          <emissive>0 0 0 1</emissive>
        </material>
      </visual>
      <collision name='collision'>
        <pose frame=''>0 0 0 0 -0 0</pose>
        <geometry>
          <box>
            <size>0.04 0.035 0.034</size>
          </box>
        </geometry>
      </collision>
    </link>
    <link name='lidar'>
      <pose frame=''>0.000271 0.036043 0.278549 0 -0 0</pose>
      <inertial>
        <mass>0.1</mass>
        <inertia>
          <ixx>4.136e-05</ixx>
          <ixy>0</ixy>
          <ixz>0</ixz>
          <iyy>4.136e-05</iyy>
          <iyz>0</iyz>
          <izz>7.605e-05</izz>
        </inertia>
        <pose frame=''>0 0 0 0 -0 0</pose>
      </inertial>
      <visual name='visual'>
        <pose frame=''>0 0 0 0 -0 0</pose>
        <geometry>
          <cylinder>
            <radius>0.039</radius>
            <length>0.02</length>
          </cylinder>
        </geometry>
        <material>
          <script>
            <uri>file://media/materials/scripts/gazebo.material</uri>
            <name>Gazebo/Black</name>
          </script>
          <ambient>0 0 0 1</ambient>
          <diffuse>0.1 0.1 0.1 1</diffuse>
          <specular>0.01 0.01 0.01 1</specular>
          <emissive>0 0 0 1</emissive>
        </material>
      </visual>
      <collision name='collision'>
        <pose frame=''>0 0 0 0 -0 0</pose>
        <geometry>
          <cylinder>
            <radius>0.039</radius>
            <length>0.02</length>
          </cylinder>
        </geometry>
      </collision>
    </link>
    <joint name='back_stack_f' type='fixed'>
      <parent>base</parent>
      <child>back_stack</child>
      <pose frame=''>0 0 0 0 -0 0</pose>
    </joint>
    <joint name='servo_l_fix' type='fixed'>
      <parent>base</parent>
      <child>left_servo</child>
      <pose frame=''>0 0 0 0 -0 0</pose>
    </joint>
    <joint name='servo_r_fix' type='fixed'>
      <parent>base</parent>
      <child>right_servo</child>
      <pose frame=''>0 0 0 0 -0 0</pose>
    </joint>
    <static>0</static>
    <joint name='left_wheel_rev' type='revolute'>
      <parent>base</parent>
      <child>left_wheel</child>
      <pose frame=''>0 0 0 0 -0 0</pose>
      <axis>
        <xyz>0 0 -1</xyz>
        <limit>
          <lower>-1.79769e+308</lower>
          <upper>1.79769e+308</upper>
          <effort>0.1</effort>
        </limit>
        <dynamics>
          <spring_reference>0</spring_reference>
          <spring_stiffness>0</spring_stiffness>
          <damping>0.001</damping>
          <friction>0.01</friction>
        </dynamics>
      </axis>
    </joint>
    <joint name='lidar_rev' type='revolute'>
      <parent>base</parent>
      <child>lidar</child>
      <pose frame=''>0 0 0 0 -0 0</pose>
      <axis>
        <xyz>0 0 1</xyz>
        <limit>
          <lower>-1.79769e+308</lower>
          <upper>1.79769e+308</upper>
          <effort>0.1</effort>
        </limit>
      </axis>
    </joint>
    <joint name='right_wheel_rev' type='revolute'>
      <parent>base</parent>
      <child>right_wheel</child>
      <pose frame=''>0 0 0 0 -0 0</pose>
      <axis>
        <xyz>0 0 -1</xyz>
        <limit>
          <lower>-1.79769e+308</lower>
          <upper>1.79769e+308</upper>
          <effort>0.1</effort>
        </limit>
        <dynamics>
          <spring_reference>0</spring_reference>
          <spring_stiffness>0</spring_stiffness>
          <damping>0.001</damping>
          <friction>0.01</friction>
        </dynamics>
      </axis>
    </joint>
  </model>
</sdf>
